<?xml version="1.0" encoding="utf-8"?>
<robot name="puppy_pi">
  <!-- Base footprint and main body -->
  <link name="base_footprint" />
  
  <joint name="base_joint" type="fixed">
    <parent link="base_footprint" />
    <child link="base_link" />
    <origin xyz="0.0 0.0 0.11" rpy="0 0 0" />
  </joint>
  
  <link name="base_link" />
  
  <joint name="dummy_joint" type="fixed">
    <parent link="base_link" />
    <child link="base_dummy" />
    <origin xyz="0.0 0.0 0.0" rpy="0 0 1.57" />
  </joint>
  
  <link name="base_dummy">
    <visual>
      <origin xyz="0 0 0" rpy="0 0 0" />
      <geometry>
        <mesh filename="package://puppy_pi_urdf/meshes/base_link.STL" />
      </geometry>
      <material name="black">
        <color rgba="0 0 0 1" />
      </material>
    </visual>
    <collision>
      <origin xyz="0 0 0" rpy="0 0 0" />
      <geometry>
        <mesh filename="package://puppy_pi_urdf/meshes/base_link.STL" />
      </geometry>
    </collision>
  </link>

  <!-- LIDAR -->
  <link name="lidar_frame">
    <visual>
      <origin xyz="0 0 0" rpy="0 0 0" />
      <geometry>
        <mesh filename="package://puppy_pi_urdf/meshes/lidar_Link.STL" />
      </geometry>
      <material name="black">
        <color rgba="0 0 0 1" />
      </material>
    </visual>
    <collision>
      <origin xyz="0 0 0" rpy="0 0 0" />
      <geometry>
        <mesh filename="package://puppy_pi_urdf/meshes/lidar_Link.STL" />
      </geometry>
    </collision>
  </link>
  
  <joint name="lidar_Joint" type="fixed">
    <origin xyz="-0.012242 -8.533E-05 0.092501" rpy="0 0 0" />
    <parent link="base_link" />
    <child link="lidar_frame" />
  </joint>

  <!-- Left Back Leg -->
  <link name="lb_link1">
    <visual>
      <origin xyz="0 0 0" rpy="0 0 0" />
      <geometry>
        <mesh filename="package://puppy_pi_urdf/meshes/lb_link1.STL" />
      </geometry>
      <material name="black">
        <color rgba="0 0 0 1" />
      </material>
    </visual>
    <collision>
      <origin xyz="0 0 0" rpy="0 0 0" />
      <geometry>
        <mesh filename="package://puppy_pi_urdf/meshes/lb_link1.STL" />
      </geometry>
    </collision>
  </link>

  <link name="lb_link2">
    <visual>
      <origin xyz="0 0 0" rpy="0 0 0" />
      <geometry>
        <mesh filename="package://puppy_pi_urdf/meshes/lb_link2.STL" />
      </geometry>
      <material name="black">
        <color rgba="0 0 0 1" />
      </material>
    </visual>
    <collision>
      <origin xyz="0 0 0" rpy="0 0 0" />
      <geometry>
        <mesh filename="package://puppy_pi_urdf/meshes/lb_link2.STL" />
      </geometry>
    </collision>
  </link>

  <link name="lb_link3">
    <visual>
      <origin xyz="0.0032 0 0.001" rpy="0 1.57 0" />
      <geometry>
        <cylinder radius="0.0095" length="0.01" />
      </geometry>
      <material name="black">
        <color rgba="0 0 0 1" />
      </material>
    </visual>
    <collision>
      <origin xyz="0.0032 0 0.001" rpy="0 1.57 0" />
      <geometry>
        <cylinder radius="0.0095" length="0.01" />
      </geometry>
    </collision>
  </link>

  <joint name="lb_joint1" type="revolute">
    <origin xyz="0.0420105649539 0.0778693100523862 0.0159880060021007" rpy="-0.752 0 0" />
    <parent link="base_dummy" />
    <child link="lb_link1" />
    <axis xyz="1 0 0" />
    <limit lower="-2" upper="2" effort="0.5" velocity="2" />
  </joint>

  <joint name="lb_joint2" type="revolute">
    <origin xyz="0.0279999999999999 -0.054600820484744 -0.045792703144293" rpy="0 0 0" />
    <parent link="lb_link1" />
    <child link="lb_link2" />
    <axis xyz="1 0 0" />
    <limit lower="-2" upper="2" effort="0.5" velocity="2" />
  </joint>

  <joint name="lb_joint3" type="fixed">
    <origin xyz="0 -0.053 -0.053" rpy="0.78 0 0" />
    <parent link="lb_link2" />
    <child link="lb_link3" />
  </joint>

  <!-- Right Back Leg -->
  <link name="rb_link1">
    <visual>
      <origin xyz="0 0 0" rpy="0 0 0" />
      <geometry>
        <mesh filename="package://puppy_pi_urdf/meshes/rb_link1.STL" />
      </geometry>
      <material name="black">
        <color rgba="0 0 0 1" />
      </material>
    </visual>
    <collision>
      <origin xyz="0 0 0" rpy="0 0 0" />
      <geometry>
        <mesh filename="package://puppy_pi_urdf/meshes/rb_link1.STL" />
      </geometry>
    </collision>
  </link>

  <link name="rb_link2">
    <visual>
      <origin xyz="0 0 0" rpy="0 0 0" />
      <geometry>
        <mesh filename="package://puppy_pi_urdf/meshes/rb_link2.STL" />
      </geometry>
      <material name="black">
        <color rgba="0 0 0 1" />
      </material>
    </visual>
    <collision>
      <origin xyz="0 0 0" rpy="0 0 0" />
      <geometry>
        <mesh filename="package://puppy_pi_urdf/meshes/rb_link2.STL" />
      </geometry>
    </collision>
  </link>

  <link name="rb_link3">
    <visual>
      <origin xyz="0.0032 0 0.001" rpy="0 1.57 0" />
      <geometry>
        <cylinder radius="0.0095" length="0.01" />
      </geometry>
      <material name="black">
        <color rgba="0 0 0 1" />
      </material>
    </visual>
    <collision>
      <origin xyz="0.0032 0 0.001" rpy="0 1.57 0" />
      <geometry>
        <cylinder radius="0.0095" length="0.01" />
      </geometry>
    </collision>
  </link>

  <joint name="rb_joint1" type="revolute">
    <origin xyz="0.0420105649539 -0.0778693100523862 0.0159880060021007" rpy="-0.752 0 0" />
    <parent link="base_dummy" />
    <child link="rb_link1" />
    <axis xyz="1 0 0" />
    <limit lower="-2" upper="2" effort="0.5" velocity="2" />
  </joint>

  <joint name="rb_joint2" type="revolute">
    <origin xyz="0.0279999999999999 0.054600820484744 -0.045792703144293" rpy="0 0 0" />
    <parent link="rb_link1" />
    <child link="rb_link2" />
    <axis xyz="1 0 0" />
    <limit lower="-2" upper="2" effort="0.5" velocity="2" />
  </joint>

  <joint name="rb_joint3" type="fixed">
    <origin xyz="0 -0.053 -0.053" rpy="0.78 0 0" />
    <parent link="rb_link2" />
    <child link="rb_link3" />
  </joint>

  <!-- Left Front Leg -->
  <link name="lf_link1">
    <visual>
      <origin xyz="0 0 0" rpy="0 0 0" />
      <geometry>
        <mesh filename="package://puppy_pi_urdf/meshes/lf_link1.STL" />
      </geometry>
      <material name="black">
        <color rgba="0 0 0 1" />
      </material>
    </visual>
    <collision>
      <origin xyz="0 0 0" rpy="0 0 0" />
      <geometry>
        <mesh filename="package://puppy_pi_urdf/meshes/lf_link1.STL" />
      </geometry>
    </collision>
  </link>

  <link name="lf_link2">
    <visual>
      <origin xyz="0 0 0" rpy="0 0 0" />
      <geometry>
        <mesh filename="package://puppy_pi_urdf/meshes/lf_link2.STL" />
      </geometry>
      <material name="black">
        <color rgba="0 0 0 1" />
      </material>
    </visual>
    <collision>
      <origin xyz="0 0 0" rpy="0 0 0" />
      <geometry>
        <mesh filename="package://puppy_pi_urdf/meshes/lf_link2.STL" />
      </geometry>
    </collision>
  </link>

  <link name="lf_link3">
    <visual>
      <origin xyz="0.0032 0 0.001" rpy="0 1.57 0" />
      <geometry>
        <cylinder radius="0.0095" length="0.01" />
      </geometry>
      <material name="black">
        <color rgba="0 0 0 1" />
      </material>
    </visual>
    <collision>
      <origin xyz="0.0032 0 0.001" rpy="0 1.57 0" />
      <geometry>
        <cylinder radius="0.0095" length="0.01" />
      </geometry>
    </collision>
  </link>

  <joint name="lf_joint1" type="revolute">
    <origin xyz="-0.0420105649539 0.0778693100523862 0.0159880060021007" rpy="-0.752 0 0" />
    <parent link="base_dummy" />
    <child link="lf_link1" />
    <axis xyz="1 0 0" />
    <limit lower="-2" upper="2" effort="0.5" velocity="2" />
  </joint>

  <joint name="lf_joint2" type="revolute">
    <origin xyz="0.0279999999999999 -0.054600820484744 -0.045792703144293" rpy="0 0 0" />
    <parent link="lf_link1" />
    <child link="lf_link2" />
    <axis xyz="1 0 0" />
    <limit lower="-2" upper="2" effort="0.5" velocity="2" />
  </joint>

  <joint name="lf_joint3" type="fixed">
    <origin xyz="0 -0.053 -0.053" rpy="0.78 0 0" />
    <parent link="lf_link2" />
    <child link="lf_link3" />
  </joint>

  <!-- Right Front Leg -->
  <link name="rf_link1">
    <visual>
      <origin xyz="0 0 0" rpy="0 0 0" />
      <geometry>
        <mesh filename="package://puppy_pi_urdf/meshes/rf_link1.STL" />
      </geometry>
      <material name="black">
        <color rgba="0 0 0 1" />
      </material>
    </visual>
    <collision>
      <origin xyz="0 0 0" rpy="0 0 0" />
      <geometry>
        <mesh filename="package://puppy_pi_urdf/meshes/rf_link1.STL" />
      </geometry>
    </collision>
  </link>

  <link name="rf_link2">
    <visual>
      <origin xyz="0 0 0" rpy="0 0 0" />
      <geometry>
        <mesh filename="package://puppy_pi_urdf/meshes/rf_link2.STL" />
      </geometry>
      <material name="black">
        <color rgba="0 0 0 1" />
      </material>
    </visual>
    <collision>
      <origin xyz="0 0 0" rpy="0 0 0" />
      <geometry>
        <mesh filename="package://puppy_pi_urdf/meshes/rf_link2.STL" />
      </geometry>
    </collision>
  </link>

  <link name="rf_link3">
    <visual>
      <origin xyz="0.0032 0 0.001" rpy="0 1.57 0" />
      <geometry>
        <cylinder radius="0.0095" length="0.01" />
      </geometry>
      <material name="black">
        <color rgba="0 0 0 1" />
      </material>
    </visual>
    <collision>
      <origin xyz="0.0032 0 0.001" rpy="0 1.57 0" />
      <geometry>
        <cylinder radius="0.0095" length="0.01" />
      </geometry>
    </collision>
  </link>

  <joint name="rf_joint1" type="revolute">
    <origin xyz="-0.0420105649539 -0.0778693100523862 0.0159880060021007" rpy="-0.752 0 0" />
    <parent link="base_dummy" />
    <child link="rf_link1" />
    <axis xyz="1 0 0" />
    <limit lower="-2" upper="2" effort="0.5" velocity="2" />
  </joint>

  <joint name="rf_joint2" type="revolute">
    <origin xyz="0.0279999999999999 0.054600820484744 -0.045792703144293" rpy="0 0 0" />
    <parent link="rf_link1" />
    <child link="rf_link2" />
    <axis xyz="1 0 0" />
    <limit lower="-2" upper="2" effort="0.5" velocity="2" />
  </joint>

  <joint name="rf_joint3" type="fixed">
    <origin xyz="0 -0.053 -0.053" rpy="0.78 0 0" />
    <parent link="rf_link2" />
    <child link="rf_link3" />
  </joint>

  <!-- Camera -->
  <link name="camera_link">
    <visual>
      <origin xyz="0 0 0" rpy="0 0 0" />
      <geometry>
        <mesh filename="package://puppy_pi_urdf/meshes/camera_link.STL" />
      </geometry>
      <material name="black">
        <color rgba="0 0 0 1" />
      </material>
    </visual>
    <collision>
      <origin xyz="0 0 0" rpy="0 0 0" />
      <geometry>
        <mesh filename="package://puppy_pi_urdf/meshes/camera_link.STL" />
      </geometry>
    </collision>
  </link>

  <joint name="camera_joint" type="fixed">
    <origin xyz="0.05 0 0.03" rpy="0 0 0" />
    <parent link="base_link" />
    <child link="camera_link" />
  </joint>

</robot>
