<?xml version="1.0" encoding="utf-8"?>
<robot name="puppy_pi">
  <!-- Base footprint and main body -->
  <link name="base_footprint" />
  
  <joint name="base_joint" type="fixed">
    <parent link="base_footprint" />
    <child link="base_link" />
    <origin xyz="0.0 0.0 0.11" rpy="0 0 0" />
  </joint>
  
  <link name="base_link" />
  
  <joint name="dummy_joint" type="fixed">
    <parent link="base_link" />
    <child link="base_dummy" />
    <origin xyz="0.0 0.0 0.0" rpy="0 0 1.57" />
  </joint>
  
  <link name="base_dummy">
    <visual>
      <origin xyz="0 0 0" rpy="0 0 0" />
      <geometry>
        <mesh filename="../meshes/base_link.STL" />
      </geometry>
      <material name="black">
        <color rgba="0 0 0 1" />
      </material>
    </visual>
    <collision>
      <origin xyz="0 0 0" rpy="0 0 0" />
      <geometry>
        <mesh filename="../meshes/base_link.STL" />
      </geometry>
    </collision>
  </link>

  <!-- LIDAR -->
  <link name="lidar_frame">
    <visual>
      <origin xyz="0 0 0" rpy="0 0 0" />
      <geometry>
        <mesh filename="../meshes/lidar_Link.STL" />
      </geometry>
      <material name="black">
        <color rgba="0 0 0 1" />
      </material>
    </visual>
    <collision>
      <origin xyz="0 0 0" rpy="0 0 0" />
      <geometry>
        <mesh filename="../meshes/lidar_Link.STL" />
      </geometry>
    </collision>
  </link>
  
  <joint name="lidar_Joint" type="fixed">
    <origin xyz="-0.012242 -8.533E-05 0.092501" rpy="0 0 0" />
    <parent link="base_link" />
    <child link="lidar_frame" />
  </joint>

  <!-- Left Back Leg -->
  <link name="lb_link1">
    <visual>
      <origin xyz="0 0 0" rpy="0 0 0" />
      <geometry>
        <mesh filename="../meshes/lb_link1.STL" />
      </geometry>
      <material name="black">
        <color rgba="0 0 0 1" />
      </material>
    </visual>
    <collision>
      <origin xyz="0 0 0" rpy="0 0 0" />
      <geometry>
        <mesh filename="../meshes/lb_link1.STL" />
      </geometry>
    </collision>
  </link>

  <link name="lb_link2">
    <visual>
      <origin xyz="0 0 0" rpy="0 0 0" />
      <geometry>
        <mesh filename="../meshes/lb_link2.STL" />
      </geometry>
      <material name="black">
        <color rgba="0 0 0 1" />
      </material>
    </visual>
    <collision>
      <origin xyz="0 0 0" rpy="0 0 0" />
      <geometry>
        <mesh filename="../meshes/lb_link2.STL" />
      </geometry>
    </collision>
  </link>

  <link name="lb_link3">
    <visual>
      <origin xyz="0 0 0" rpy="0 0 0" />
      <geometry>
        <cylinder radius="0.01" length="0.05" />
      </geometry>
      <material name="black">
        <color rgba="0 0 0 1" />
      </material>
    </visual>
    <collision>
      <origin xyz="0 0 0" rpy="0 0 0" />
      <geometry>
        <cylinder radius="0.01" length="0.05" />
      </geometry>
    </collision>
  </link>

  <joint name="lb_joint1" type="revolute">
    <origin xyz="-0.065 -0.065 0.0" rpy="0 0 0" />
    <parent link="base_link" />
    <child link="lb_link1" />
    <axis xyz="0 0 1" />
    <limit lower="-1.57" upper="1.57" effort="100" velocity="1" />
  </joint>

  <joint name="lb_joint2" type="revolute">
    <origin xyz="0.0 0.0 0.0" rpy="0 0 0" />
    <parent link="lb_link1" />
    <child link="lb_link2" />
    <axis xyz="0 0 1" />
    <limit lower="-1.57" upper="1.57" effort="100" velocity="1" />
  </joint>

  <joint name="lb_joint3" type="revolute">
    <origin xyz="0.0 0.0 0.0" rpy="0 0 0" />
    <parent link="lb_link2" />
    <child link="lb_link3" />
    <axis xyz="0 0 1" />
    <limit lower="-1.57" upper="1.57" effort="100" velocity="1" />
  </joint>

  <!-- Right Back Leg -->
  <link name="rb_link1">
    <visual>
      <origin xyz="0 0 0" rpy="0 0 0" />
      <geometry>
        <mesh filename="../meshes/rb_link1.STL" />
      </geometry>
      <material name="black">
        <color rgba="0 0 0 1" />
      </material>
    </visual>
    <collision>
      <origin xyz="0 0 0" rpy="0 0 0" />
      <geometry>
        <mesh filename="../meshes/rb_link1.STL" />
      </geometry>
    </collision>
  </link>

  <link name="rb_link2">
    <visual>
      <origin xyz="0 0 0" rpy="0 0 0" />
      <geometry>
        <mesh filename="../meshes/rb_link2.STL" />
      </geometry>
      <material name="black">
        <color rgba="0 0 0 1" />
      </material>
    </visual>
    <collision>
      <origin xyz="0 0 0" rpy="0 0 0" />
      <geometry>
        <mesh filename="../meshes/rb_link2.STL" />
      </geometry>
    </collision>
  </link>

  <link name="rb_link3">
    <visual>
      <origin xyz="0 0 0" rpy="0 0 0" />
      <geometry>
        <cylinder radius="0.01" length="0.05" />
      </geometry>
      <material name="black">
        <color rgba="0 0 0 1" />
      </material>
    </visual>
    <collision>
      <origin xyz="0 0 0" rpy="0 0 0" />
      <geometry>
        <cylinder radius="0.01" length="0.05" />
      </geometry>
    </collision>
  </link>

  <joint name="rb_joint1" type="revolute">
    <origin xyz="-0.065 0.065 0.0" rpy="0 0 0" />
    <parent link="base_link" />
    <child link="rb_link1" />
    <axis xyz="0 0 1" />
    <limit lower="-1.57" upper="1.57" effort="100" velocity="1" />
  </joint>

  <joint name="rb_joint2" type="revolute">
    <origin xyz="0.0 0.0 0.0" rpy="0 0 0" />
    <parent link="rb_link1" />
    <child link="rb_link2" />
    <axis xyz="0 0 1" />
    <limit lower="-1.57" upper="1.57" effort="100" velocity="1" />
  </joint>

  <joint name="rb_joint3" type="revolute">
    <origin xyz="0.0 0.0 0.0" rpy="0 0 0" />
    <parent link="rb_link2" />
    <child link="rb_link3" />
    <axis xyz="0 0 1" />
    <limit lower="-1.57" upper="1.57" effort="100" velocity="1" />
  </joint>

  <!-- Left Front Leg -->
  <link name="lf_link1">
    <visual>
      <origin xyz="0 0 0" rpy="0 0 0" />
      <geometry>
        <mesh filename="../meshes/lf_link1.STL" />
      </geometry>
      <material name="black">
        <color rgba="0 0 0 1" />
      </material>
    </visual>
    <collision>
      <origin xyz="0 0 0" rpy="0 0 0" />
      <geometry>
        <mesh filename="../meshes/lf_link1.STL" />
      </geometry>
    </collision>
  </link>

  <link name="lf_link2">
    <visual>
      <origin xyz="0 0 0" rpy="0 0 0" />
      <geometry>
        <mesh filename="../meshes/lf_link2.STL" />
      </geometry>
      <material name="black">
        <color rgba="0 0 0 1" />
      </material>
    </visual>
    <collision>
      <origin xyz="0 0 0" rpy="0 0 0" />
      <geometry>
        <mesh filename="../meshes/lf_link2.STL" />
      </geometry>
    </collision>
  </link>

  <link name="lf_link3">
    <visual>
      <origin xyz="0 0 0" rpy="0 0 0" />
      <geometry>
        <cylinder radius="0.01" length="0.05" />
      </geometry>
      <material name="black">
        <color rgba="0 0 0 1" />
      </material>
    </visual>
    <collision>
      <origin xyz="0 0 0" rpy="0 0 0" />
      <geometry>
        <cylinder radius="0.01" length="0.05" />
      </geometry>
    </collision>
  </link>

  <joint name="lf_joint1" type="revolute">
    <origin xyz="0.065 -0.065 0.0" rpy="0 0 0" />
    <parent link="base_link" />
    <child link="lf_link1" />
    <axis xyz="0 0 1" />
    <limit lower="-1.57" upper="1.57" effort="100" velocity="1" />
  </joint>

  <joint name="lf_joint2" type="revolute">
    <origin xyz="0.0 0.0 0.0" rpy="0 0 0" />
    <parent link="lf_link1" />
    <child link="lf_link2" />
    <axis xyz="0 0 1" />
    <limit lower="-1.57" upper="1.57" effort="100" velocity="1" />
  </joint>

  <joint name="lf_joint3" type="revolute">
    <origin xyz="0.0 0.0 0.0" rpy="0 0 0" />
    <parent link="lf_link2" />
    <child link="lf_link3" />
    <axis xyz="0 0 1" />
    <limit lower="-1.57" upper="1.57" effort="100" velocity="1" />
  </joint>

  <!-- Right Front Leg -->
  <link name="rf_link1">
    <visual>
      <origin xyz="0 0 0" rpy="0 0 0" />
      <geometry>
        <mesh filename="../meshes/rf_link1.STL" />
      </geometry>
      <material name="black">
        <color rgba="0 0 0 1" />
      </material>
    </visual>
    <collision>
      <origin xyz="0 0 0" rpy="0 0 0" />
      <geometry>
        <mesh filename="../meshes/rf_link1.STL" />
      </geometry>
    </collision>
  </link>

  <link name="rf_link2">
    <visual>
      <origin xyz="0 0 0" rpy="0 0 0" />
      <geometry>
        <mesh filename="../meshes/rf_link2.STL" />
      </geometry>
      <material name="black">
        <color rgba="0 0 0 1" />
      </material>
    </visual>
    <collision>
      <origin xyz="0 0 0" rpy="0 0 0" />
      <geometry>
        <mesh filename="../meshes/rf_link2.STL" />
      </geometry>
    </collision>
  </link>

  <link name="rf_link3">
    <visual>
      <origin xyz="0 0 0" rpy="0 0 0" />
      <geometry>
        <cylinder radius="0.01" length="0.05" />
      </geometry>
      <material name="black">
        <color rgba="0 0 0 1" />
      </material>
    </visual>
    <collision>
      <origin xyz="0 0 0" rpy="0 0 0" />
      <geometry>
        <cylinder radius="0.01" length="0.05" />
      </geometry>
    </collision>
  </link>

  <joint name="rf_joint1" type="revolute">
    <origin xyz="0.065 0.065 0.0" rpy="0 0 0" />
    <parent link="base_link" />
    <child link="rf_link1" />
    <axis xyz="0 0 1" />
    <limit lower="-1.57" upper="1.57" effort="100" velocity="1" />
  </joint>

  <joint name="rf_joint2" type="revolute">
    <origin xyz="0.0 0.0 0.0" rpy="0 0 0" />
    <parent link="rf_link1" />
    <child link="rf_link2" />
    <axis xyz="0 0 1" />
    <limit lower="-1.57" upper="1.57" effort="100" velocity="1" />
  </joint>

  <joint name="rf_joint3" type="revolute">
    <origin xyz="0.0 0.0 0.0" rpy="0 0 0" />
    <parent link="rf_link2" />
    <child link="rf_link3" />
    <axis xyz="0 0 1" />
    <limit lower="-1.57" upper="1.57" effort="100" velocity="1" />
  </joint>

  <!-- Camera -->
  <link name="camera_link">
    <visual>
      <origin xyz="0 0 0" rpy="0 0 0" />
      <geometry>
        <mesh filename="../meshes/camera_link.STL" />
      </geometry>
      <material name="black">
        <color rgba="0 0 0 1" />
      </material>
    </visual>
    <collision>
      <origin xyz="0 0 0" rpy="0 0 0" />
      <geometry>
        <mesh filename="../meshes/camera_link.STL" />
      </geometry>
    </collision>
  </link>

  <joint name="camera_joint" type="fixed">
    <origin xyz="0.0 0.0 0.05" rpy="0 0 0" />
    <parent link="base_link" />
    <child link="camera_link" />
  </joint>

</robot>
